<mujoco model="humanoid">
    <compiler angle="degree" inertiafromgeom="true"/>
    <default>
        <joint armature="1" damping="1" limited="true"/>
        <geom conaffinity="1" condim="4" solref=".006 1" contype="1" margin=".00" gap=".00" material="geom" rgba="0.8 0.6 .4 1"  friction="2.0 .05 .05"/>
        <motor ctrllimited="true" ctrlrange="-.4 .4"/>
    </default>
    <option integrator="RK4" iterations="50" solver="PGS" timestep="0.003">
        <!-- <flags solverstat="enable" energy="enable"/>-->
    </option>
    <size nkey="5" nuser_geom="1"/>
    <visual>
        <map fogend="5" fogstart="3"/>
    </visual>
    <asset>
        <texture builtin="gradient" height="100" rgb1=".4 .5 .6" rgb2="0 0 0" type="skybox" width="100"/>
        <!-- <texture builtin="gradient" height="100" rgb1="1 1 1" rgb2="0 0 0" type="skybox" width="100"/>-->
        <texture builtin="flat" height="1278" mark="cross" markrgb="1 1 1" name="texgeom" random="0.01" rgb1="0.8 0.6 0.4" rgb2="0.8 0.6 0.4" type="cube" width="127"/>
        <texture builtin="checker" height="100" name="texplane" rgb1="0 0 0" rgb2="0.8 0.8 0.8" type="2d" width="100"/>
        <material name="MatPlane" reflectance="0.5" shininess="1" specular="1" texrepeat="60 60" texture="texplane"/>
        <material name="geom" texture="texgeom" texuniform="true"/>
        <mesh name="foot_mesh_right" file="foot_right.obj"/>
        <mesh name="foot_mesh_left" scale="1 -1 1" file="foot_right.obj"/>
        <!-- Non-convex mesh collision isn't supported -->
        <!-- <mesh name="hook_mesh_right" scale="1.5 0.5 2"file="hook.obj"/>
        <mesh name="hook_mesh_left" scale="1.5 0.5 2" file="hook.obj"/> -->
        <!-- <mesh name="ladder" file="ladder.obj"/> -->
    </asset>
    <worldbody>
        <light cutoff="100" diffuse="1 1 1" dir="-0 0 -1.3" directional="true" exponent="1" pos="0 0 1.3" specular=".1 .1 .1"/>
        <geom condim="3" friction="1 .1 .1" material="MatPlane" name="floor" pos="0 0 0" group="1" rgba="0.8 0.9 0.8 1" size="20 20 0.125" type="plane"/> <!-- 0 -->
        <!-- <body name="topout" pos="1.6 0 1.8">
            <geom name="topout_box" size="0.8 2 0.05" type="box"/>
        </body> -->
        <body name="ladder" pos="0.4 0 0">
            <!-- <geom condim="3" friction="1 .1 .1" name="ladder" pos="0.3 0 0" type="mesh" mesh="ladder"/> -->
            <geom name="rung0" type="capsule" size="0.01 2" pos="-.1 0 .2" group="1" axisangle="1 0 0 90" rgba="0.8 0.4 0 1"/> <!-- 1 -->
            <geom name="rung1" type="capsule" size="0.01 2" pos="-.05 0 .4" group="1" axisangle="1 0 0 90" rgba="0.8 0.4 0 1"/>
            <geom name="rung2" type="capsule" size="0.01 2" pos="0 0 .6" group="1" axisangle="1 0 0 90" rgba="0.8 0.4 0 1"/>
            <geom name="rung3" type="capsule" size="0.01 2" pos=".05 0 .8" group="1" axisangle="1 0 0 90" rgba="0.8 0.4 0 1"/>
            <geom name="rung4" type="capsule" size="0.01 2" pos=".1 0 1.0" group="1" axisangle="1 0 0 90" rgba="0.8 0.4 0 1"/>
            <geom name="rung5" type="capsule" size="0.01 2" pos=".15 0 1.2" group="1" axisangle="1 0 0 90" rgba="0.8 0.4 0 1"/>
            <geom name="rung6" type="capsule" size="0.01 2" pos=".2 0 1.4" group="1" axisangle="1 0 0 90" rgba="0.8 0.4 0 1"/>
            <geom name="rung7" type="capsule" size="0.01 2" pos=".25 0 1.6" group="1" axisangle="1 0 0 90" rgba="0.8 0.4 0 1"/>
            <geom name="rung8" type="capsule" size="0.01 2" pos=".3 0 1.8" group="1" axisangle="1 0 0 90" rgba="0.8 0.4 0 1"/>
            <geom name="rung9" type="capsule" size="0.01 2" pos=".35 0 2.0" group="1" axisangle="1 0 0 90" rgba="0.8 0.4 0 1"/>
            <geom name="rung10" type="capsule" size="0.01 2" pos=".4 0 2.2" group="1" axisangle="1 0 0 90" rgba="0.8 0.4 0 1"/>
            <geom name="rung11" type="capsule" size="0.01 2" pos=".45 0 2.4" group="1" axisangle="1 0 0 90" rgba="0.8 0.4 0 1"/>
            <geom name="rung12" type="capsule" size="0.01 2" pos=".5 0 2.6" group="1" axisangle="1 0 0 90" rgba="0.8 0.4 0 1"/>
            <geom name="rung13" type="capsule" size="0.01 2" pos=".55 0 2.8" group="1" axisangle="1 0 0 90" rgba="0.8 0.4 0 1"/>
            <geom name="rung14" type="capsule" size="0.01 2" pos=".6 0 3.0" group="1" axisangle="1 0 0 90" rgba="0.8 0.4 0 1"/>
        </body>
        <body name="torso" pos="0 0 1.24">
            <camera name="track" mode="trackcom" pos="0 -4 0" xyaxes="1 0 0 0 0 1"/>
            <joint armature="0" damping="0" limited="false" name="root" pos="0 0 0" stiffness="0" type="free"/>
            <geom fromto="0 -.07 0 0 .07 0" name="torso1" size="0.07" type="capsule"/> <!-- 16 -->
            <geom name="head" pos="0 0 .19" size=".09" type="sphere" user="258"/>
            <geom fromto="-.01 -.06 -.12 -.01 .06 -.12" name="uwaist" size="0.06" type="capsule"/>
            <body name="lwaist" pos="-.01 0 -0.260" quat="1.000 0 -0.002 0"> 
                <geom fromto="0 -.06 0 0 .06 0" name="lwaist" size="0.06" type="capsule"/> <!-- 19 -->
                <joint armature="0.02" axis="0 0 1" damping="5" name="abdomen_z" pos="0 0 0.065" range="-45 45" stiffness="20" type="hinge"/>
                <joint armature="0.02" axis="0 1 0" damping="5" name="abdomen_y" pos="0 0 0.065" range="-75 30" stiffness="10" type="hinge"/>
                <body name="pelvis" pos="0 0 -0.165" quat="1.000 0 -0.002 0">
                    <joint armature="0.02" axis="1 0 0" damping="5" name="abdomen_x" pos="0 0 0.1" range="-35 35" stiffness="10" type="hinge"/>
                    <geom fromto="-.02 -.07 0 -.02 .07 0" name="butt" size="0.09" type="capsule"/> <!-- 20 -->
                    <body name="right_thigh" pos="0 -0.1 -0.04">
                        <joint armature="0.01" axis="1 0 0" damping="5" name="right_hip_x" pos="0 0 0" range="-25 5" stiffness="10" type="hinge"/>
                        <joint armature="0.01" axis="0 0 1" damping="5" name="right_hip_z" pos="0 0 0" range="-60 35" stiffness="10" type="hinge"/>
                        <joint armature="0.0080" axis="0 1 0" damping="5" name="right_hip_y" pos="0 0 0" range="-110 20" stiffness="20" type="hinge"/>
                        <geom fromto="0 0 0 0 0.01 -.34" name="right_thigh1" size="0.06" type="capsule"/> <!-- 21 -->
                        <body name="right_shin" pos="0 0.01 -0.403">
                            <joint armature="0.0060" axis="0 -1 0" damping="5" name="right_knee" pos="0 0 .02" range="-160 -2" stiffness="10" type="hinge"/>
                            <geom fromto="0 0 0 0 0 -.3" name="right_shin1" size="0.049" type="capsule"/> <!-- 22 -->
                            <body name="right_foot" pos="0 0 -0.32">
                                <joint armature="0.0028" axis="1 0 0" damping="5" name="right_ankle_x" pos="-.022 0 0" range="-3 3" stiffness="5" type="hinge"/>
                                <joint armature="0.0028" axis="0 1 0" damping="5" name="right_ankle_y" pos="-.022 0 0" range="-20 20" stiffness="5" type="hinge"/>
                                <!-- <geom name="right_foot" type="mesh" mesh="foot_mesh_right" pos="0 0 -0.03" user="0"/> -->
                                <geom name="right_foot" pos=".025 0 -0.02" size="0.13 0.06 0.02" type="box"/> <!-- 23 -->
                            </body>
                        </body>
                    </body>
                    <body name="left_thigh" pos="0 0.1 -0.04">
                        <joint armature="0.01" axis="-1 0 0" damping="5" name="left_hip_x" pos="0 0 0" range="-25 5" stiffness="10" type="hinge"/>
                        <joint armature="0.01" axis="0 0 -1" damping="5" name="left_hip_z" pos="0 0 0" range="-60 35" stiffness="10" type="hinge"/>
                        <joint armature="0.01" axis="0 1 0" damping="5" name="left_hip_y" pos="0 0 0" range="-110 20" stiffness="20" type="hinge"/>
                        <geom fromto="0 0 0 0 -0.01 -.34" name="left_thigh1" size="0.06" type="capsule"/> <!-- 24 -->
                        <body name="left_shin" pos="0 -0.01 -0.403">
                            <joint armature="0.0060" axis="0 -1 0" damping="5" name="left_knee" pos="0 0 .02" range="-160 -2" stiffness="10" type="hinge"/>
                            <geom fromto="0 0 0 0 0 -.3" name="left_shin1" size="0.049" type="capsule"/> <!-- 25 -->
                            <body name="left_foot" pos="0 0 -0.32">
                                <joint armature="0.0028" axis="1 0 0" damping="5" name="left_ankle_x" pos="-.022 0 0" range="-3 3" stiffness="5" type="hinge"/>
                                <joint armature="0.0028" axis="0 1 0" damping="5" name="left_ankle_y" pos="-.022 0 0" range="-20 20" stiffness="5" type="hinge"/>
                                <!-- <geom name="left_foot" type="mesh" mesh="foot_mesh_left" pos="0 0 -0.03" user="0"/> -->
                                <geom name="left_foot" pos=".025 0 -0.02" size="0.13 0.06 0.02" type="box"/> <!-- 26 -->
                            </body>
                        </body>
                    </body>
                </body>
            </body>
            <body name="right_upper_arm" pos="0 -0.17 0.06">
                <joint armature="0.0068" axis="0 1 0" damping="2" name="right_shoulder1" pos="0 0 0" range="-85 60" stiffness="2" type="hinge"/>
                <!-- <joint armature="0.0051" axis="0 -1 1" name="right_shoulder2" pos="0 0 0" range="-85 60" stiffness="1" type="hinge"/>
                <joint armature="0.0051" axis="1 -1 -1" name="right_shoulder3" pos="0 0 0" range="-85 85" stiffness="1" type="hinge"/> -->
                <geom fromto="0 0 0 .196 0 -.196" name="right_uarm1" size="0.04 0.16" type="capsule"/> <!-- 27 -->
                <body name="right_lower_arm" pos=".22 0 -.22">
                    <joint armature="0.0028" axis="0 1 0" damping="2" name="right_elbow" pos="0 0 0" range="-70 70" stiffness="2" type="hinge"/>
                    <geom fromto="0.01 0 0.01 .206 0 .206" name="right_larm" size="0.031" type="capsule"/> <!-- 28 -->
                    <body name="right_hand" pos=".232 0 .232">
                        <joint armature="0.0028" axis="0 1 0" damping="2" name="right_wrist" pos="0 0 0" range="-40 60" stiffness="2" type="hinge"/>
                        <geom name="right_palm" size="0.03" type="sphere"/> <!-- 29 -->
                        <body name="finger_base_r" pos=".0245 0 .0245">
                            <joint armature="0.002" axis="0 1 0" name="finger_base_joint_r" pos="0 0 0" range="10 80" stiffness="0.02" type="hinge"/>
                            <geom name="finger_base_r1" fromto="0 .033 0 .033 .033 .033" size=".012" type="capsule"/> <!-- 30 -->
                            <geom name="finger_base_r2" fromto=".0 .0 .0 .033 0 .033" size=".012" type="capsule"/> 
                            <geom name="finger_base_r3" fromto=".0 -.033 0 .033 -.033 .033" size=".012" type="capsule"/> 
                            <site name="base_site_r" pos=".015 0 -.005" size="0.012" rgba="0 0 0 .2"/>
                            <body name="finger_mid_r" pos=".034 0 .034">
                                <joint armature="0.002" axis="0 1 0" name="finger_mid_joint_r" pos="0 0 0" range="10 90" stiffness="0.02" type="hinge"/>
                                <geom name="finger_mid_r1" fromto="0 .033 0 .032 .033 .032" size=".012" type="capsule"/> <!-- 33 -->
                                <geom name="finger_mid_r2" fromto="0 0 0 .032 .0 .032" size=".012" type="capsule"/> 
                                <geom name="finger_mid_r3" fromto="0 -.033 0 .032 -.033 .032" size=".012" type="capsule"/> 
                                <site name="mid_site_r" pos=".015 0 -.005" size="0.012" rgba="0 0 0 .2"/>
                                <body name="finger_tip_r" pos=".034 0 .034">
                                    <joint armature="0.002" axis="0 1 0" name="finger_tip_joint_r" pos="0 0 0" range="10 80" stiffness=".02" type="hinge"/>
                                    <geom name="finger_tip_r1" fromto=".0 .033 0 .029 .033 .029" size=".012" type="capsule"/> <!-- 36 -->
                                    <geom name="finger_tip_r2" fromto=".0 .0 .0 .029 0 .029" size=".012" type="capsule"/> 
                                    <geom name="finger_tip_r3" fromto=".0 -.033 0 .029 -.033 .029" size=".012" type="capsule"/> 
                                    <site name="top_site_r" pos=".015 0 -.005" size="0.012" rgba="0 0 0 .2"/>
                                    <site name="tip_site_r" pos=".041 .0 .021" size="0.012" rgba="0 0 0 .2"/>
                                </body>
                            </body>
                        </body>
                    </body>
                    <camera pos="0 0 0"/>
                </body>
            </body>
            <body name="left_upper_arm" pos="0 0.17 0.06">
                <joint armature="0.0068" axis="0 1 0" damping="2" name="left_shoulder1" pos="0 0 0" range="-85 60" stiffness="2" type="hinge"/>
                <!-- <joint armature="0.0051" axis="0 1 1" name="left_shoulder2" pos="0 0 0" range="-60 85" stiffness="1" type="hinge"/>
                <joint armature="0.0051" axis="-1 -1 1" name="left_shoulder3" pos="0 0 0" range="-60 85" stiffness="1" type="hinge"/> -->
                <geom fromto="0 0 0 .196 0 -.196" name="left_uarm1" size="0.04 0.16" type="capsule"/> <!-- 39 -->
                <body name="left_lower_arm" pos=".22 0 -.22">
                    <joint armature="0.0028" axis="0 1 0" damping="2" name="left_elbow" pos="0 0 0" range="-70 70" stiffness="2" type="hinge"/>
                    <geom fromto="0.01 0 0.01 .206 0 .206" name="left_larm" size="0.031" type="capsule"/> <!-- 40 -->
                    <body name="left_hand" pos=".232 0 .232">
                        <joint armature="0.0028" axis="0 1 0" damping="2" name="left_wrist" pos="0 0 0" range="-40 60" stiffness="2" type="hinge"/>
                        <geom name="left_palm" size="0.03" type="sphere"/> <!-- 41 -->
                        <body name="finger_base_l" pos=".0245 0 .0245">
                            <joint armature="0.002" axis="0 1 0" name="finger_base_joint_l" pos="0 0 0" range="10 80" stiffness="0.02" type="hinge"/>
                            <geom name="finger_base_l1" fromto="0 .033 0 .033 .033 .033" size=".012" type="capsule"/> <!-- 42 -->
                            <geom name="finger_base_l2" fromto=".0 .0 .0 .033 0 .033" size=".012" type="capsule"/> 
                            <geom name="finger_base_l3" fromto=".0 -.033 0 .033 -.033 .033" size=".012" type="capsule"/> 
                            <site name="base_site_l" pos=".015 0 -.005" size="0.012" rgba="0 0 0 .2"/>
                            <body name="finger_mid_l" pos=".034 0 .034">
                                <joint armature="0.002" axis="0 1 0" name="finger_mid_joint_l" pos="0 0 0" range="10 90" stiffness="0.02" type="hinge"/>
                                <geom name="finger_mid_l1" fromto="0 .033 0 .032 .033 .032" size=".012" type="capsule"/> <!-- 45 -->
                                <geom name="finger_mid_l2" fromto="0 0 0 .032 .0 .032" size=".012" type="capsule"/> 
                                <geom name="finger_mid_l3" fromto="0 -.033 0 .032 -.033 .032" size=".012" type="capsule"/> 
                                <site name="mid_site_l" pos=".015 0 -.005" size="0.012" rgba="0 0 0 .2"/>
                                <body name="finger_tip_l" pos=".034 0 .034">
                                    <joint armature="0.002" axis="0 1 0" name="finger_tip_joint_l" pos="0 0 0" range="10 80" stiffness=".02" type="hinge"/>
                                    <geom name="finger_tip_l1" fromto=".0 .033 0 .029 .033 .029" size=".012" type="capsule"/> <!-- 48 -->
                                    <geom name="finger_tip_l2" fromto=".0 .0 .0 .029 0 .029" size=".012" type="capsule"/> 
                                    <geom name="finger_tip_l3" fromto=".0 -.033 0 .029 -.033 .029" size=".012" type="capsule"/> 
                                    <site name="top_site_l" pos=".015 0 -.005" size="0.012" rgba="0 0 0 .2"/>
                                    <site name="tip_site_l" pos=".041 .0 .021" size="0.012" rgba="0 0 0 .2"/>
                                </body>
                            </body>
                        </body>
                    </body>
                </body>
            </body>
        </body>
    </worldbody>
    <tendon>
        <fixed name="left_hipknee">
            <joint coef="-1" joint="left_hip_y"/>
            <joint coef="1" joint="left_knee"/>
        </fixed>
        <fixed name="right_hipknee">
            <joint coef="-1" joint="right_hip_y"/>
            <joint coef="1" joint="right_knee"/>
        </fixed>
        <spatial name="finger_tendon_r" width="0.005" rgba=".4 .6 .4 1"> 
            <site site="base_site_r"/>
            <site site="mid_site_r"/>
            <site site="top_site_r"/>
            <site site="tip_site_r"/>
        </spatial>
        <spatial name="finger_tendon_l" width="0.005" rgba=".4 .6 .4 1"> 
            <site site="base_site_l"/>
            <site site="mid_site_l"/>
            <site site="top_site_l"/>
            <site site="tip_site_l"/>
        </spatial>
    </tendon>

    <actuator>
        <motor gear="100" joint="right_shoulder1" name="right_shoulder1"/>
        <!-- <motor gear="100" joint="right_shoulder2" name="right_shoulder2"/> -->
        <!-- <motor gear="100" joint="right_shoulder3" name="right_shoulder3"/> -->
        <motor gear="100" joint="left_shoulder1" name="left_shoulder1"/>
        <!-- <motor gear="100" joint="left_shoulder2" name="left_shoulder2"/> -->
        <!-- <motor gear="100" joint="left_shoulder3" name="left_shoulder3"/> -->
        <motor gear="100" joint="right_elbow" name="right_elbow"/>
        <motor gear="100" joint="left_elbow" name="left_elbow"/>
        <motor gear="30" joint="right_wrist" name="right_wrist"/>
        <motor gear="30" joint="left_wrist" name="left_wrist"/>
        <motor gear="100" joint="abdomen_y" name="abdomen_y"/>
        <motor gear="100" joint="abdomen_z" name="abdomen_z"/>
        <motor gear="100" joint="abdomen_x" name="abdomen_x"/>
        <motor gear="100" joint="right_hip_x" name="right_hip_x"/>
        <motor gear="100" joint="right_hip_z" name="right_hip_z"/>
        <motor gear="300" joint="right_hip_y" name="right_hip_y"/>
        <motor gear="100" joint="left_hip_x" name="left_hip_x"/>
        <motor gear="100" joint="left_hip_z" name="left_hip_z"/>
        <motor gear="300" joint="left_hip_y" name="left_hip_y"/>
        <motor gear="200" joint="right_knee" name="right_knee"/>
        <motor gear="200" joint="left_knee" name="left_knee"/>
        <motor gear="40" joint="right_ankle_x" name="right_ankle_x"/>
        <motor gear="40" joint="right_ankle_y" name="right_ankle_y"/>
        <motor gear="40" joint="left_ankle_x" name="left_ankle_x"/>
        <motor gear="40" joint="left_ankle_y" name="left_ankle_y"/>
        <motor tendon="finger_tendon_r" ctrlrange="-0.4 0.4" gear="2000" name="fingers_r"/>
        <motor tendon="finger_tendon_l" ctrlrange="-0.4 0.4" gear="2000" name="fingers_l"/>
    </actuator>
    <!-- <sensor>
        <touch name="foot_l" site="foot_l"/>
        <touch name="foot_r" site="foot_r"/>
    </sensor> -->
    <keyframe>
    <key name="keyframe1"
    qpos="
   0       
   0       
   1.24     
   1       
   0       
   0       
   0       
   0       
   0       
   0       
   0       
   0       
  -1.1     
  -1.3     
   0       
  -0.11    
   0       
   0       
   0       
   0       
   0       
   0       
   0.098   
   0.21    
  -0.26    
   0.21    
   0.67    
   0.59    
   0.067   
   0.12    
   0       
   0.37    
   0.52    
   0.68"/>
    </keyframe> 
</mujoco>
